10/09/20 (22:35:53) | ERROR: <urlopen error [Errno -3] Temporary failure in name resolution>
Traceback (most recent call last):
  File "/usr/lib/python3.8/urllib/request.py", line 1350, in do_open
    h.request(req.get_method(), req.selector, req.data, headers,
  File "/usr/lib/python3.8/http/client.py", line 1255, in request
    self._send_request(method, url, body, headers, encode_chunked)
  File "/usr/lib/python3.8/http/client.py", line 1301, in _send_request
    self.endheaders(body, encode_chunked=encode_chunked)
  File "/usr/lib/python3.8/http/client.py", line 1250, in endheaders
    self._send_output(message_body, encode_chunked=encode_chunked)
  File "/usr/lib/python3.8/http/client.py", line 1010, in _send_output
    self.send(msg)
  File "/usr/lib/python3.8/http/client.py", line 950, in send
    self.connect()
  File "/usr/lib/python3.8/http/client.py", line 1417, in connect
    super().connect()
  File "/usr/lib/python3.8/http/client.py", line 921, in connect
    self.sock = self._create_connection(
  File "/usr/lib/python3.8/socket.py", line 787, in create_connection
    for res in getaddrinfo(host, port, 0, SOCK_STREAM):
  File "/usr/lib/python3.8/socket.py", line 918, in getaddrinfo
    for res in _socket.getaddrinfo(host, port, family, type, proto, flags):
socket.gaierror: [Errno -3] Temporary failure in name resolution

During handling of the above exception, another exception occurred:

Traceback (most recent call last):
  File "/usr/bin/bpytop", line 3973, in _checker
    with urllib.request.urlopen("https://github.com/aristocratos/bpytop/raw/master/bpytop.py", timeout=5) as source: # type: ignore
  File "/usr/lib/python3.8/urllib/request.py", line 222, in urlopen
    return opener.open(url, data, timeout)
  File "/usr/lib/python3.8/urllib/request.py", line 525, in open
    response = self._open(req, data)
  File "/usr/lib/python3.8/urllib/request.py", line 542, in _open
    result = self._call_chain(self.handle_open, protocol, protocol +
  File "/usr/lib/python3.8/urllib/request.py", line 502, in _call_chain
    result = func(*args)
  File "/usr/lib/python3.8/urllib/request.py", line 1393, in https_open
    return self.do_open(http.client.HTTPSConnection, req,
  File "/usr/lib/python3.8/urllib/request.py", line 1353, in do_open
    raise URLError(err)
urllib.error.URLError: <urlopen error [Errno -3] Temporary failure in name resolution>
10/09/20 (22:45:00) | ERROR: <urlopen error [Errno -3] Temporary failure in name resolution>
Traceback (most recent call last):
  File "/usr/lib/python3.8/urllib/request.py", line 1350, in do_open
    h.request(req.get_method(), req.selector, req.data, headers,
  File "/usr/lib/python3.8/http/client.py", line 1255, in request
    self._send_request(method, url, body, headers, encode_chunked)
  File "/usr/lib/python3.8/http/client.py", line 1301, in _send_request
    self.endheaders(body, encode_chunked=encode_chunked)
  File "/usr/lib/python3.8/http/client.py", line 1250, in endheaders
    self._send_output(message_body, encode_chunked=encode_chunked)
  File "/usr/lib/python3.8/http/client.py", line 1010, in _send_output
    self.send(msg)
  File "/usr/lib/python3.8/http/client.py", line 950, in send
    self.connect()
  File "/usr/lib/python3.8/http/client.py", line 1417, in connect
    super().connect()
  File "/usr/lib/python3.8/http/client.py", line 921, in connect
    self.sock = self._create_connection(
  File "/usr/lib/python3.8/socket.py", line 787, in create_connection
    for res in getaddrinfo(host, port, 0, SOCK_STREAM):
  File "/usr/lib/python3.8/socket.py", line 918, in getaddrinfo
    for res in _socket.getaddrinfo(host, port, family, type, proto, flags):
socket.gaierror: [Errno -3] Temporary failure in name resolution

During handling of the above exception, another exception occurred:

Traceback (most recent call last):
  File "/usr/bin/bpytop", line 3973, in _checker
    with urllib.request.urlopen("https://github.com/aristocratos/bpytop/raw/master/bpytop.py", timeout=5) as source: # type: ignore
  File "/usr/lib/python3.8/urllib/request.py", line 222, in urlopen
    return opener.open(url, data, timeout)
  File "/usr/lib/python3.8/urllib/request.py", line 525, in open
    response = self._open(req, data)
  File "/usr/lib/python3.8/urllib/request.py", line 542, in _open
    result = self._call_chain(self.handle_open, protocol, protocol +
  File "/usr/lib/python3.8/urllib/request.py", line 502, in _call_chain
    result = func(*args)
  File "/usr/lib/python3.8/urllib/request.py", line 1393, in https_open
    return self.do_open(http.client.HTTPSConnection, req,
  File "/usr/lib/python3.8/urllib/request.py", line 1353, in do_open
    raise URLError(err)
urllib.error.URLError: <urlopen error [Errno -3] Temporary failure in name resolution>
23/09/20 (20:28:26) | ERROR: Exception when sending signal 15 to pid 1250
23/09/20 (20:28:26) | ERROR: [Errno 1] Operation not permitted
Traceback (most recent call last):
  File "/usr/bin/bpytop", line 4349, in process_keys
    os.kill(pid, sig)
PermissionError: [Errno 1] Operation not permitted
06/10/20 (18:18:32) | ERROR: <urlopen error [Errno -3] Temporary failure in name resolution>
Traceback (most recent call last):
  File "/usr/lib/python3.8/urllib/request.py", line 1350, in do_open
    h.request(req.get_method(), req.selector, req.data, headers,
  File "/usr/lib/python3.8/http/client.py", line 1255, in request
    self._send_request(method, url, body, headers, encode_chunked)
  File "/usr/lib/python3.8/http/client.py", line 1301, in _send_request
    self.endheaders(body, encode_chunked=encode_chunked)
  File "/usr/lib/python3.8/http/client.py", line 1250, in endheaders
    self._send_output(message_body, encode_chunked=encode_chunked)
  File "/usr/lib/python3.8/http/client.py", line 1010, in _send_output
    self.send(msg)
  File "/usr/lib/python3.8/http/client.py", line 950, in send
    self.connect()
  File "/usr/lib/python3.8/http/client.py", line 1417, in connect
    super().connect()
  File "/usr/lib/python3.8/http/client.py", line 921, in connect
    self.sock = self._create_connection(
  File "/usr/lib/python3.8/socket.py", line 787, in create_connection
    for res in getaddrinfo(host, port, 0, SOCK_STREAM):
  File "/usr/lib/python3.8/socket.py", line 918, in getaddrinfo
    for res in _socket.getaddrinfo(host, port, family, type, proto, flags):
socket.gaierror: [Errno -3] Temporary failure in name resolution

During handling of the above exception, another exception occurred:

Traceback (most recent call last):
  File "/usr/bin/bpytop", line 4258, in _checker
    with urllib.request.urlopen("https://github.com/aristocratos/bpytop/raw/master/bpytop.py", timeout=5) as source: # type: ignore
  File "/usr/lib/python3.8/urllib/request.py", line 222, in urlopen
    return opener.open(url, data, timeout)
  File "/usr/lib/python3.8/urllib/request.py", line 525, in open
    response = self._open(req, data)
  File "/usr/lib/python3.8/urllib/request.py", line 542, in _open
    result = self._call_chain(self.handle_open, protocol, protocol +
  File "/usr/lib/python3.8/urllib/request.py", line 502, in _call_chain
    result = func(*args)
  File "/usr/lib/python3.8/urllib/request.py", line 1393, in https_open
    return self.do_open(http.client.HTTPSConnection, req,
  File "/usr/lib/python3.8/urllib/request.py", line 1353, in do_open
    raise URLError(err)
urllib.error.URLError: <urlopen error [Errno -3] Temporary failure in name resolution>
10/10/20 (14:37:02) | ERROR: Exception when sending signal 15 to pid 624
10/10/20 (14:37:02) | ERROR: [Errno 1] Operation not permitted
Traceback (most recent call last):
  File "/usr/bin/bpytop", line 4665, in process_keys
    os.kill(pid, sig)
PermissionError: [Errno 1] Operation not permitted
10/10/20 (16:13:58) | ERROR: <urlopen error [Errno -3] Temporary failure in name resolution>
Traceback (most recent call last):
  File "/usr/lib/python3.8/urllib/request.py", line 1350, in do_open
    h.request(req.get_method(), req.selector, req.data, headers,
  File "/usr/lib/python3.8/http/client.py", line 1255, in request
    self._send_request(method, url, body, headers, encode_chunked)
  File "/usr/lib/python3.8/http/client.py", line 1301, in _send_request
    self.endheaders(body, encode_chunked=encode_chunked)
  File "/usr/lib/python3.8/http/client.py", line 1250, in endheaders
    self._send_output(message_body, encode_chunked=encode_chunked)
  File "/usr/lib/python3.8/http/client.py", line 1010, in _send_output
    self.send(msg)
  File "/usr/lib/python3.8/http/client.py", line 950, in send
    self.connect()
  File "/usr/lib/python3.8/http/client.py", line 1417, in connect
    super().connect()
  File "/usr/lib/python3.8/http/client.py", line 921, in connect
    self.sock = self._create_connection(
  File "/usr/lib/python3.8/socket.py", line 787, in create_connection
    for res in getaddrinfo(host, port, 0, SOCK_STREAM):
  File "/usr/lib/python3.8/socket.py", line 918, in getaddrinfo
    for res in _socket.getaddrinfo(host, port, family, type, proto, flags):
socket.gaierror: [Errno -3] Temporary failure in name resolution

During handling of the above exception, another exception occurred:

Traceback (most recent call last):
  File "/usr/bin/bpytop", line 4273, in _checker
    with urllib.request.urlopen("https://github.com/aristocratos/bpytop/raw/master/bpytop.py", timeout=5) as source: # type: ignore
  File "/usr/lib/python3.8/urllib/request.py", line 222, in urlopen
    return opener.open(url, data, timeout)
  File "/usr/lib/python3.8/urllib/request.py", line 525, in open
    response = self._open(req, data)
  File "/usr/lib/python3.8/urllib/request.py", line 542, in _open
    result = self._call_chain(self.handle_open, protocol, protocol +
  File "/usr/lib/python3.8/urllib/request.py", line 502, in _call_chain
    result = func(*args)
  File "/usr/lib/python3.8/urllib/request.py", line 1393, in https_open
    return self.do_open(http.client.HTTPSConnection, req,
  File "/usr/lib/python3.8/urllib/request.py", line 1353, in do_open
    raise URLError(err)
urllib.error.URLError: <urlopen error [Errno -3] Temporary failure in name resolution>
10/10/20 (16:14:15) | ERROR: Exception when sending signal 15 to pid 1694
10/10/20 (16:14:15) | ERROR: [Errno 1] Operation not permitted
Traceback (most recent call last):
  File "/usr/bin/bpytop", line 4680, in process_keys
    os.kill(pid, sig)
PermissionError: [Errno 1] Operation not permitted
15/10/20 (17:59:44) | ERROR: Exception when sending signal 15 to pid 31830
15/10/20 (17:59:44) | ERROR: [Errno 1] Operation not permitted
Traceback (most recent call last):
  File "/usr/bin/bpytop", line 4680, in process_keys
    os.kill(pid, sig)
PermissionError: [Errno 1] Operation not permitted
22/10/20 (16:15:03) | ERROR: Exception when sending signal 15 to pid 1571
22/10/20 (16:15:03) | ERROR: [Errno 1] Operation not permitted
Traceback (most recent call last):
  File "/usr/bin/bpytop", line 4680, in process_keys
    os.kill(pid, sig)
PermissionError: [Errno 1] Operation not permitted
